Workbook

Sheet Config
A1: 📋 PROJECT CONFIGURATION
A3: Project List | C3: Instructions
A4: ODC Cleanup | C4: 1. Add new project names to column A (starting row 4)
A5: Datastore Reclamation | C5: 2. Keep names EXACTLY matching the sheet tab names
A6: Retired VM Cleanup | C6: 3. Delete project names when projects are removed
A7: Zerto Scripts | C7: 4. Dashboard and Demos will auto-update
C8: 5. Maximum supported: 20 projects
B10: =COUNTA(A4:A23)-COUNTIF(A4:A23,"← Add more projects above") -> 4
A24: ← Add more projects above

Sheet Dashboard
B2: PROJECT PERFORMANCE DASHBOARD V3
B4: Total Actions | C4: =SUM(C12:C31) -> 76
B5: Completed | C5: =SUM(D12:D31) -> 0
B6: In Progress | C6: =SUM(E12:E31) -> 0
B7: Overdue | C7: =SUM(F12:F31) -> 1
B8: Not Started | C8: =SUM(G12:G31) -> 75
J10: CHALLENGES TRACKER
B11: Project Name | C11: Total | D11: Completed | E11: In Progress | F11: Overdue | G11: Not Started | H11: Overall Progress | J11: Project Name | K11: % with Challenges
B12: =IF(Config!A4="","",Config!A4) -> ODC Cleanup | C12: =IF(Config!A4="","",IFERROR(COUNTA(INDIRECT("'"&Config!A4&"'!B2:B1000")),0)) -> 19 | D12: =IF(Config!A4="","",IFERROR(COUNTIF(INDIRECT("'"&Config!A4&"'!B2:B1000"),"Completed"),0)) -> 0 | E12: =IF(Config!A4="","",IFERROR(COUNTIF(INDIRECT("'"&Config!A4&"'!B2:B1000"),"In Progress"),0)) -> 0 | F12: =IF(Config!A4="","",IFERROR(COUNTIF(INDIRECT("'"&Config!A4&"'!B2:B1000"),"Overdue"),0)) -> 1 | G12: =IF(Config!A4="","",IFERROR(COUNTIF(INDIRECT("'"&Config!A4&"'!B2:B1000"),"Not Started"),0)) -> 18 | H12: =IF(Config!A4="","",IFERROR(COUNTIF(INDIRECT("'"&Config!A4&"'!B2:B1000"),"Completed")/COUNTA(INDIRECT("'"&Config!A4&"'!B2:B1000")),0)) -> 0 | J12: =IF(Config!A4="","",Config!A4) -> ODC Cleanup | K12: =IF(Config!A4="","",IFERROR((COUNTA(INDIRECT("'"&Config!A4&"'!J2:J1000"))-COUNTIF(INDIRECT("'"&Config!A4&"'!J2:J1000"),"None"))/COUNTA(INDIRECT("'"&Config!A4&"'!B2:B1000")),0)) -> 0.052631579
B13: =IF(Config!A5="","",Config!A5) -> Datastore Reclamation | C13: =IF(Config!A5="","",IFERROR(COUNTA(INDIRECT("'"&Config!A5&"'!B2:B1000")),0)) -> 19 | D13: =IF(Config!A5="","",IFERROR(COUNTIF(INDIRECT("'"&Config!A5&"'!B2:B1000"),"Completed"),0)) -> 0 | E13: =IF(Config!A5="","",IFERROR(COUNTIF(INDIRECT("'"&Config!A5&"'!B2:B1000"),"In Progress"),0)) -> 0 | F13: =IF(Config!A5="","",IFERROR(COUNTIF(INDIRECT("'"&Config!A5&"'!B2:B1000"),"Overdue"),0)) -> 0 | G13: =IF(Config!A5="","",IFERROR(COUNTIF(INDIRECT("'"&Config!A5&"'!B2:B1000"),"Not Started"),0)) -> 19 | H13: =IF(Config!A5="","",IFERROR(COUNTIF(INDIRECT("'"&Config!A5&"'!B2:B1000"),"Completed")/COUNTA(INDIRECT("'"&Config!A5&"'!B2:B1000")),0)) -> 0 | J13: =IF(Config!A5="","",Config!A5) -> Datastore Reclamation | K13: =IF(Config!A5="","",IFERROR((COUNTA(INDIRECT("'"&Config!A5&"'!J2:J1000"))-COUNTIF(INDIRECT("'"&Config!A5&"'!J2:J1000"),"None"))/COUNTA(INDIRECT("'"&Config!A5&"'!B2:B1000")),0)) -> 0
B14: =IF(Config!A6="","",Config!A6) -> Retired VM Cleanup | C14: =IF(Config!A6="","",IFERROR(COUNTA(INDIRECT("'"&Config!A6&"'!B2:B1000")),0)) -> 19 | D14: =IF(Config!A6="","",IFERROR(COUNTIF(INDIRECT("'"&Config!A6&"'!B2:B1000"),"Completed"),0)) -> 0 | E14: =IF(Config!A6="","",IFERROR(COUNTIF(INDIRECT("'"&Config!A6&"'!B2:B1000"),"In Progress"),0)) -> 0 | F14: =IF(Config!A6="","",IFERROR(COUNTIF(INDIRECT("'"&Config!A6&"'!B2:B1000"),"Overdue"),0)) -> 0 | G14: =IF(Config!A6="","",IFERROR(COUNTIF(INDIRECT("'"&Config!A6&"'!B2:B1000"),"Not Started"),0)) -> 19 | H14: =IF(Config!A6="","",IFERROR(COUNTIF(INDIRECT("'"&Config!A6&"'!B2:B1000"),"Completed")/COUNTA(INDIRECT("'"&Config!A6&"'!B2:B1000")),0)) -> 0 | J14: =IF(Config!A6="","",Config!A6) -> Retired VM Cleanup | K14: =IF(Config!A6="","",IFERROR((COUNTA(INDIRECT("'"&Config!A6&"'!J2:J1000"))-COUNTIF(INDIRECT("'"&Config!A6&"'!J2:J1000"),"None"))/COUNTA(INDIRECT("'"&Config!A6&"'!B2:B1000")),0)) -> 0
B15: =IF(Config!A7="","",Config!A7) -> Zerto Scripts | C15: =IF(Config!A7="","",IFERROR(COUNTA(INDIRECT("'"&Config!A7&"'!B2:B1000")),0)) -> 19 | D15: =IF(Config!A7="","",IFERROR(COUNTIF(INDIRECT("'"&Config!A7&"'!B2:B1000"),"Completed"),0)) -> 0 | E15: =IF(Config!A7="","",IFERROR(COUNTIF(INDIRECT("'"&Config!A7&"'!B2:B1000"),"In Progress"),0)) -> 0 | F15: =IF(Config!A7="","",IFERROR(COUNTIF(INDIRECT("'"&Config!A7&"'!B2:B1000"),"Overdue"),0)) -> 0 | G15: =IF(Config!A7="","",IFERROR(COUNTIF(INDIRECT("'"&Config!A7&"'!B2:B1000"),"Not Started"),0)) -> 19 | H15: =IF(Config!A7="","",IFERROR(COUNTIF(INDIRECT("'"&Config!A7&"'!B2:B1000"),"Completed")/COUNTA(INDIRECT("'"&Config!A7&"'!B2:B1000")),0)) -> 0 | J15: =IF(Config!A7="","",Config!A7) -> Zerto Scripts | K15: =IF(Config!A7="","",IFERROR((COUNTA(INDIRECT("'"&Config!A7&"'!J2:J1000"))-COUNTIF(INDIRECT("'"&Config!A7&"'!J2:J1000"),"None"))/COUNTA(INDIRECT("'"&Config!A7&"'!B2:B1000")),0)) -> 0
B16: =IF(Config!A8="","",Config!A8) | C16: =IF(Config!A8="","",IFERROR(COUNTA(INDIRECT("'"&Config!A8&"'!B2:B1000")),0)) | D16: =IF(Config!A8="","",IFERROR(COUNTIF(INDIRECT("'"&Config!A8&"'!B2:B1000"),"Completed"),0)) | E16: =IF(Config!A8="","",IFERROR(COUNTIF(INDIRECT("'"&Config!A8&"'!B2:B1000"),"In Progress"),0)) | F16: =IF(Config!A8="","",IFERROR(COUNTIF(INDIRECT("'"&Config!A8&"'!B2:B1000"),"Overdue"),0)) | G16: =IF(Config!A8="","",IFERROR(COUNTIF(INDIRECT("'"&Config!A8&"'!B2:B1000"),"Not Started"),0)) | H16: =IF(Config!A8="","",IFERROR(COUNTIF(INDIRECT("'"&Config!A8&"'!B2:B1000"),"Completed")/COUNTA(INDIRECT("'"&Config!A8&"'!B2:B1000")),0)) | J16: =IF(Config!A8="","",Config!A8) | K16: =IF(Config!A8="","",IFERROR((COUNTA(INDIRECT("'"&Config!A8&"'!J2:J1000"))-COUNTIF(INDIRECT("'"&Config!A8&"'!J2:J1000"),"None"))/COUNTA(INDIRECT("'"&Config!A8&"'!B2:B1000")),0))
B17: =IF(Config!A9="","",Config!A9) | C17: =IF(Config!A9="","",IFERROR(COUNTA(INDIRECT("'"&Config!A9&"'!B2:B1000")),0)) | D17: =IF(Config!A9="","",IFERROR(COUNTIF(INDIRECT("'"&Config!A9&"'!B2:B1000"),"Completed"),0)) | E17: =IF(Config!A9="","",IFERROR(COUNTIF(INDIRECT("'"&Config!A9&"'!B2:B1000"),"In Progress"),0)) | F17: =IF(Config!A9="","",IFERROR(COUNTIF(INDIRECT("'"&Config!A9&"'!B2:B1000"),"Overdue"),0)) | G17: =IF(Config!A9="","",IFERROR(COUNTIF(INDIRECT("'"&Config!A9&"'!B2:B1000"),"Not Started"),0)) | H17: =IF(Config!A9="","",IFERROR(COUNTIF(INDIRECT("'"&Config!A9&"'!B2:B1000"),"Completed")/COUNTA(INDIRECT("'"&Config!A9&"'!B2:B1000")),0)) | J17: =IF(Config!A9="","",Config!A9) | K17: =IF(Config!A9="","",IFERROR((COUNTA(INDIRECT("'"&Config!A9&"'!J2:J1000"))-COUNTIF(INDIRECT("'"&Config!A9&"'!J2:J1000"),"None"))/COUNTA(INDIRECT("'"&Config!A9&"'!B2:B1000")),0))
B18: =IF(Config!A10="","",Config!A10) | C18: =IF(Config!A10="","",IFERROR(COUNTA(INDIRECT("'"&Config!A10&"'!B2:B1000")),0)) | D18: =IF(Config!A10="","",IFERROR(COUNTIF(INDIRECT("'"&Config!A10&"'!B2:B1000"),"Completed"),0)) | E18: =IF(Config!A10="","",IFERROR(COUNTIF(INDIRECT("'"&Config!A10&"'!B2:B1000"),"In Progress"),0)) | F18: =IF(Config!A10="","",IFERROR(COUNTIF(INDIRECT("'"&Config!A10&"'!B2:B1000"),"Overdue"),0)) | G18: =IF(Config!A10="","",IFERROR(COUNTIF(INDIRECT("'"&Config!A10&"'!B2:B1000"),"Not Started"),0)) | H18: =IF(Config!A10="","",IFERROR(COUNTIF(INDIRECT("'"&Config!A10&"'!B2:B1000"),"Completed")/COUNTA(INDIRECT("'"&Config!A10&"'!B2:B1000")),0)) | J18: =IF(Config!A10="","",Config!A10) | K18: =IF(Config!A10="","",IFERROR((COUNTA(INDIRECT("'"&Config!A10&"'!J2:J1000"))-COUNTIF(INDIRECT("'"&Config!A10&"'!J2:J1000"),"None"))/COUNTA(INDIRECT("'"&Config!A10&"'!B2:B1000")),0))
B19: =IF(Config!A11="","",Config!A11) | C19: =IF(Config!A11="","",IFERROR(COUNTA(INDIRECT("'"&Config!A11&"'!B2:B1000")),0)) | D19: =IF(Config!A11="","",IFERROR(COUNTIF(INDIRECT("'"&Config!A11&"'!B2:B1000"),"Completed"),0)) | E19: =IF(Config!A11="","",IFERROR(COUNTIF(INDIRECT("'"&Config!A11&"'!B2:B1000"),"In Progress"),0)) | F19: =IF(Config!A11="","",IFERROR(COUNTIF(INDIRECT("'"&Config!A11&"'!B2:B1000"),"Overdue"),0)) | G19: =IF(Config!A11="","",IFERROR(COUNTIF(INDIRECT("'"&Config!A11&"'!B2:B1000"),"Not Started"),0)) | H19: =IF(Config!A11="","",IFERROR(COUNTIF(INDIRECT("'"&Config!A11&"'!B2:B1000"),"Completed")/COUNTA(INDIRECT("'"&Config!A11&"'!B2:B1000")),0)) | J19: =IF(Config!A11="","",Config!A11) | K19: =IF(Config!A11="","",IFERROR((COUNTA(INDIRECT("'"&Config!A11&"'!J2:J1000"))-COUNTIF(INDIRECT("'"&Config!A11&"'!J2:J1000"),"None"))/COUNTA(INDIRECT("'"&Config!A11&"'!B2:B1000")),0))
B20: =IF(Config!A12="","",Config!A12) | C20: =IF(Config!A12="","",IFERROR(COUNTA(INDIRECT("'"&Config!A12&"'!B2:B1000")),0)) | D20: =IF(Config!A12="","",IFERROR(COUNTIF(INDIRECT("'"&Config!A12&"'!B2:B1000"),"Completed"),0)) | E20: =IF(Config!A12="","",IFERROR(COUNTIF(INDIRECT("'"&Config!A12&"'!B2:B1000"),"In Progress"),0)) | F20: =IF(Config!A12="","",IFERROR(COUNTIF(INDIRECT("'"&Config!A12&"'!B2:B1000"),"Overdue"),0)) | G20: =IF(Config!A12="","",IFERROR(COUNTIF(INDIRECT("'"&Config!A12&"'!B2:B1000"),"Not Started"),0)) | H20: =IF(Config!A12="","",IFERROR(COUNTIF(INDIRECT("'"&Config!A12&"'!B2:B1000"),"Completed")/COUNTA(INDIRECT("'"&Config!A12&"'!B2:B1000")),0)) | J20: =IF(Config!A12="","",Config!A12) | K20: =IF(Config!A12="","",IFERROR((COUNTA(INDIRECT("'"&Config!A12&"'!J2:J1000"))-COUNTIF(INDIRECT("'"&Config!A12&"'!J2:J1000"),"None"))/COUNTA(INDIRECT("'"&Config!A12&"'!B2:B1000")),0))
B21: =IF(Config!A13="","",Config!A13) | C21: =IF(Config!A13="","",IFERROR(COUNTA(INDIRECT("'"&Config!A13&"'!B2:B1000")),0)) | D21: =IF(Config!A13="","",IFERROR(COUNTIF(INDIRECT("'"&Config!A13&"'!B2:B1000"),"Completed"),0)) | E21: =IF(Config!A13="","",IFERROR(COUNTIF(INDIRECT("'"&Config!A13&"'!B2:B1000"),"In Progress"),0)) | F21: =IF(Config!A13="","",IFERROR(COUNTIF(INDIRECT("'"&Config!A13&"'!B2:B1000"),"Overdue"),0)) | G21: =IF(Config!A13="","",IFERROR(COUNTIF(INDIRECT("'"&Config!A13&"'!B2:B1000"),"Not Started"),0)) | H21: =IF(Config!A13="","",IFERROR(COUNTIF(INDIRECT("'"&Config!A13&"'!B2:B1000"),"Completed")/COUNTA(INDIRECT("'"&Config!A13&"'!B2:B1000")),0)) | J21: =IF(Config!A13="","",Config!A13) | K21: =IF(Config!A13="","",IFERROR((COUNTA(INDIRECT("'"&Config!A13&"'!J2:J1000"))-COUNTIF(INDIRECT("'"&Config!A13&"'!J2:J1000"),"None"))/COUNTA(INDIRECT("'"&Config!A13&"'!B2:B1000")),0))
B22: =IF(Config!A14="","",Config!A14) | C22: =IF(Config!A14="","",IFERROR(COUNTA(INDIRECT("'"&Config!A14&"'!B2:B1000")),0)) | D22: =IF(Config!A14="","",IFERROR(COUNTIF(INDIRECT("'"&Config!A14&"'!B2:B1000"),"Completed"),0)) | E22: =IF(Config!A14="","",IFERROR(COUNTIF(INDIRECT("'"&Config!A14&"'!B2:B1000"),"In Progress"),0)) | F22: =IF(Config!A14="","",IFERROR(COUNTIF(INDIRECT("'"&Config!A14&"'!B2:B1000"),"Overdue"),0)) | G22: =IF(Config!A14="","",IFERROR(COUNTIF(INDIRECT("'"&Config!A14&"'!B2:B1000"),"Not Started"),0)) | H22: =IF(Config!A14="","",IFERROR(COUNTIF(INDIRECT("'"&Config!A14&"'!B2:B1000"),"Completed")/COUNTA(INDIRECT("'"&Config!A14&"'!B2:B1000")),0)) | J22: =IF(Config!A14="","",Config!A14) | K22: =IF(Config!A14="","",IFERROR((COUNTA(INDIRECT("'"&Config!A14&"'!J2:J1000"))-COUNTIF(INDIRECT("'"&Config!A14&"'!J2:J1000"),"None"))/COUNTA(INDIRECT("'"&Config!A14&"'!B2:B1000")),0))
B23: =IF(Config!A15="","",Config!A15) | C23: =IF(Config!A15="","",IFERROR(COUNTA(INDIRECT("'"&Config!A15&"'!B2:B1000")),0)) | D23: =IF(Config!A15="","",IFERROR(COUNTIF(INDIRECT("'"&Config!A15&"'!B2:B1000"),"Completed"),0)) | E23: =IF(Config!A15="","",IFERROR(COUNTIF(INDIRECT("'"&Config!A15&"'!B2:B1000"),"In Progress"),0)) | F23: =IF(Config!A15="","",IFERROR(COUNTIF(INDIRECT("'"&Config!A15&"'!B2:B1000"),"Overdue"),0)) | G23: =IF(Config!A15="","",IFERROR(COUNTIF(INDIRECT("'"&Config!A15&"'!B2:B1000"),"Not Started"),0)) | H23: =IF(Config!A15="","",IFERROR(COUNTIF(INDIRECT("'"&Config!A15&"'!B2:B1000"),"Completed")/COUNTA(INDIRECT("'"&Config!A15&"'!B2:B1000")),0)) | J23: =IF(Config!A15="","",Config!A15) | K23: =IF(Config!A15="","",IFERROR((COUNTA(INDIRECT("'"&Config!A15&"'!J2:J1000"))-COUNTIF(INDIRECT("'"&Config!A15&"'!J2:J1000"),"None"))/COUNTA(INDIRECT("'"&Config!A15&"'!B2:B1000")),0))
... B31: =IF(Config!A23="","",Config!A23) | C31: =IF(Config!A23="","",IFERROR(COUNTA(INDIRECT("'"&Config!A23&"'!B2:B1000")),0)) | D31: =IF(Config!A23="","",IFERROR(COUNTIF(INDIRECT("'"&Config!A23&"'!B2:B1000"),"Completed"),0)) | E31: =IF(Config!A23="","",IFERROR(COUNTIF(INDIRECT("'"&Config!A23&"'!B2:B1000"),"In Progress"),0)) | F31: =IF(Config!A23="","",IFERROR(COUNTIF(INDIRECT("'"&Config!A23&"'!B2:B1000"),"Overdue"),0)) | G31: =IF(Config!A23="","",IFERROR(COUNTIF(INDIRECT("'"&Config!A23&"'!B2:B1000"),"Not Started"),0)) | H31: =IF(Config!A23="","",IFERROR(COUNTIF(INDIRECT("'"&Config!A23&"'!B2:B1000"),"Completed")/COUNTA(INDIRECT("'"&Config!A23&"'!B2:B1000")),0)) | J31: =IF(Config!A23="","",Config!A23) | K31: =IF(Config!A23="","",IFERROR((COUNTA(INDIRECT("'"&Config!A23&"'!J2:J1000"))-COUNTIF(INDIRECT("'"&Config!A23&"'!J2:J1000"),"None"))/COUNTA(INDIRECT("'"&Config!A23&"'!B2:B1000")),0))

Sheet Demos
A1: 📊 PROJECT PORTFOLIO ANALYTICS DASHBOARD
A2: Generated: Dynamic | Data Source: All Project Sheets via Config
A4: 🎯 PORTFOLIO KPIs | R4: Status Breakdown
A5: KPI Metric | B5: Value | C5: Description | R5: Completed | S5: =B8 -> 0
A6: Total Projects | B6: =COUNTA(Config!A4:A23) -> 4 | C6: Count of project sheets | R6: In Progress | S6: =B9 -> 0
A7: Total Action Items | B7: =B36 -> 76 | C7: Sum of all items (minus headers) | R7: Overdue | S7: =B10 -> 1
A8: Completed Items | B8: =C36 -> 0 | C8: Items with Completed status | R8: Not Started | S8: =B11 -> 75
A9: In Progress Items | B9: =D36 -> 0 | C9: Items currently In Progress
A10: Overdue Items | B10: =E36 -> 1 | C10: Items marked Overdue | R10: Health Scores
A11: Not Started Items | B11: =F36 -> 75 | C11: Items Not Started | R11: =IF(Config!A4="","",Config!A4) -> ODC Cleanup | S11: =IF(Config!A4="","",F193) -> 0.47368421
A12: Overall Completion Rate | B12: =G36 -> 0 | C12: Completed / Total Items | R12: =IF(Config!A5="","",Config!A5) -> Datastore Reclamation | S12: =IF(Config!A5="","",F194) -> 0.5
R13: =IF(Config!A6="","",Config!A6) -> Retired VM Cleanup | S13: =IF(Config!A6="","",F195) -> 0.5
A14: 📋 PROJECT STATUS BREAKDOWN | R14: =IF(Config!A7="","",Config!A7) -> Zerto Scripts | S14: =IF(Config!A7="","",F196) -> 0.5
A15: Project Name | B15: Total | C15: Completed | D15: In Progress | E15: Overdue | F15: Not Started | G15: Progress % | R15: =IF(Config!A8="","",Config!A8) | S15: =IF(Config!A8="","",F197)
A16: =IF(Config!A4="","",Config!A4) -> ODC Cleanup | B16: =IF(Config!A4="","",IFERROR(COUNTA(INDIRECT("'"&Config!A4&"'!B2:B1000")),0)) -> 19 | C16: =IF(Config!A4="","",IFERROR(COUNTIF(INDIRECT("'"&Config!A4&"'!B2:B1000"),"Completed"),0)) -> 0 | D16: =IF(Config!A4="","",IFERROR(COUNTIF(INDIRECT("'"&Config!A4&"'!B2:B1000"),"In Progress"),0)) -> 0 | E16: =IF(Config!A4="","",IFERROR(COUNTIF(INDIRECT("'"&Config!A4&"'!B2:B1000"),"Overdue"),0)) -> 1 | F16: =IF(Config!A4="","",IFERROR(COUNTIF(INDIRECT("'"&Config!A4&"'!B2:B1000"),"Not Started"),0)) -> 18 | G16: =IF(Config!A4="","",IFERROR(COUNTIF(INDIRECT("'"&Config!A4&"'!B2:B1000"),"Completed")/COUNTA(INDIRECT("'"&Config!A4&"'!B2:B1000")),0)) -> 0 | R16: =IF(Config!A9="","",Config!A9) | S16: =IF(Config!A9="","",F198)
A17: =IF(Config!A5="","",Config!A5) -> Datastore Reclamation | B17: =IF(Config!A5="","",IFERROR(COUNTA(INDIRECT("'"&Config!A5&"'!B2:B1000")),0)) -> 19 | C17: =IF(Config!A5="","",IFERROR(COUNTIF(INDIRECT("'"&Config!A5&"'!B2:B1000"),"Completed"),0)) -> 0 | D17: =IF(Config!A5="","",IFERROR(COUNTIF(INDIRECT("'"&Config!A5&"'!B2:B1000"),"In Progress"),0)) -> 0 | E17: =IF(Config!A5="","",IFERROR(COUNTIF(INDIRECT("'"&Config!A5&"'!B2:B1000"),"Overdue"),0)) -> 0 | F17: =IF(Config!A5="","",IFERROR(COUNTIF(INDIRECT("'"&Config!A5&"'!B2:B1000"),"Not Started"),0)) -> 19 | G17: =IF(Config!A5="","",IFERROR(COUNTIF(INDIRECT("'"&Config!A5&"'!B2:B1000"),"Completed")/COUNTA(INDIRECT("'"&Config!A5&"'!B2:B1000")),0)) -> 0 | R17: =IF(Config!A10="","",Config!A10) | S17: =IF(Config!A10="","",F199)
A18: =IF(Config!A6="","",Config!A6) -> Retired VM Cleanup | B18: =IF(Config!A6="","",IFERROR(COUNTA(INDIRECT("'"&Config!A6&"'!B2:B1000")),0)) -> 19 | C18: =IF(Config!A6="","",IFERROR(COUNTIF(INDIRECT("'"&Config!A6&"'!B2:B1000"),"Completed"),0)) -> 0 | D18: =IF(Config!A6="","",IFERROR(COUNTIF(INDIRECT("'"&Config!A6&"'!B2:B1000"),"In Progress"),0)) -> 0 | E18: =IF(Config!A6="","",IFERROR(COUNTIF(INDIRECT("'"&Config!A6&"'!B2:B1000"),"Overdue"),0)) -> 0 | F18: =IF(Config!A6="","",IFERROR(COUNTIF(INDIRECT("'"&Config!A6&"'!B2:B1000"),"Not Started"),0)) -> 19 | G18: =IF(Config!A6="","",IFERROR(COUNTIF(INDIRECT("'"&Config!A6&"'!B2:B1000"),"Completed")/COUNTA(INDIRECT("'"&Config!A6&"'!B2:B1000")),0)) -> 0 | R18: =IF(Config!A11="","",Config!A11) | S18: =IF(Config!A11="","",F200)
A19: =IF(Config!A7="","",Config!A7) -> Zerto Scripts | B19: =IF(Config!A7="","",IFERROR(COUNTA(INDIRECT("'"&Config!A7&"'!B2:B1000")),0)) -> 19 | C19: =IF(Config!A7="","",IFERROR(COUNTIF(INDIRECT("'"&Config!A7&"'!B2:B1000"),"Completed"),0)) -> 0 | D19: =IF(Config!A7="","",IFERROR(COUNTIF(INDIRECT("'"&Config!A7&"'!B2:B1000"),"In Progress"),0)) -> 0 | E19: =IF(Config!A7="","",IFERROR(COUNTIF(INDIRECT("'"&Config!A7&"'!B2:B1000"),"Overdue"),0)) -> 0 | F19: =IF(Config!A7="","",IFERROR(COUNTIF(INDIRECT("'"&Config!A7&"'!B2:B1000"),"Not Started"),0)) -> 19 | G19: =IF(Config!A7="","",IFERROR(COUNTIF(INDIRECT("'"&Config!A7&"'!B2:B1000"),"Completed")/COUNTA(INDIRECT("'"&Config!A7&"'!B2:B1000")),0)) -> 0 | R19: =IF(Config!A12="","",Config!A12) | S19: =IF(Config!A12="","",F201)
A20: =IF(Config!A8="","",Config!A8) | B20: =IF(Config!A8="","",IFERROR(COUNTA(INDIRECT("'"&Config!A8&"'!B2:B1000")),0)) | C20: =IF(Config!A8="","",IFERROR(COUNTIF(INDIRECT("'"&Config!A8&"'!B2:B1000"),"Completed"),0)) | D20: =IF(Config!A8="","",IFERROR(COUNTIF(INDIRECT("'"&Config!A8&"'!B2:B1000"),"In Progress"),0)) | E20: =IF(Config!A8="","",IFERROR(COUNTIF(INDIRECT("'"&Config!A8&"'!B2:B1000"),"Overdue"),0)) | F20: =IF(Config!A8="","",IFERROR(COUNTIF(INDIRECT("'"&Config!A8&"'!B2:B1000"),"Not Started"),0)) | G20: =IF(Config!A8="","",IFERROR(COUNTIF(INDIRECT("'"&Config!A8&"'!B2:B1000"),"Completed")/COUNTA(INDIRECT("'"&Config!A8&"'!B2:B1000")),0)) | R20: =IF(Config!A13="","",Config!A13) | S20: =IF(Config!A13="","",F202)
A21: =IF(Config!A9="","",Config!A9) | B21: =IF(Config!A9="","",IFERROR(COUNTA(INDIRECT("'"&Config!A9&"'!B2:B1000")),0)) | C21: =IF(Config!A9="","",IFERROR(COUNTIF(INDIRECT("'"&Config!A9&"'!B2:B1000"),"Completed"),0)) | D21: =IF(Config!A9="","",IFERROR(COUNTIF(INDIRECT("'"&Config!A9&"'!B2:B1000"),"In Progress"),0)) | E21: =IF(Config!A9="","",IFERROR(COUNTIF(INDIRECT("'"&Config!A9&"'!B2:B1000"),"Overdue"),0)) | F21: =IF(Config!A9="","",IFERROR(COUNTIF(INDIRECT("'"&Config!A9&"'!B2:B1000"),"Not Started"),0)) | G21: =IF(Config!A9="","",IFERROR(COUNTIF(INDIRECT("'"&Config!A9&"'!B2:B1000"),"Completed")/COUNTA(INDIRECT("'"&Config!A9&"'!B2:B1000")),0)) | R21: =IF(Config!A14="","",Config!A14) | S21: =IF(Config!A14="","",F203)
A22: =IF(Config!A10="","",Config!A10) | B22: =IF(Config!A10="","",IFERROR(COUNTA(INDIRECT("'"&Config!A10&"'!B2:B1000")),0)) | C22: =IF(Config!A10="","",IFERROR(COUNTIF(INDIRECT("'"&Config!A10&"'!B2:B1000"),"Completed"),0)) | D22: =IF(Config!A10="","",IFERROR(COUNTIF(INDIRECT("'"&Config!A10&"'!B2:B1000"),"In Progress"),0)) | E22: =IF(Config!A10="","",IFERROR(COUNTIF(INDIRECT("'"&Config!A10&"'!B2:B1000"),"Overdue"),0)) | F22: =IF(Config!A10="","",IFERROR(COUNTIF(INDIRECT("'"&Config!A10&"'!B2:B1000"),"Not Started"),0)) | G22: =IF(Config!A10="","",IFERROR(COUNTIF(INDIRECT("'"&Config!A10&"'!B2:B1000"),"Completed")/COUNTA(INDIRECT("'"&Config!A10&"'!B2:B1000")),0)) | R22: =IF(Config!A15="","",Config!A15) | S22: =IF(Config!A15="","",F204)
A23: =IF(Config!A11="","",Config!A11) | B23: =IF(Config!A11="","",IFERROR(COUNTA(INDIRECT("'"&Config!A11&"'!B2:B1000")),0)) | C23: =IF(Config!A11="","",IFERROR(COUNTIF(INDIRECT("'"&Config!A11&"'!B2:B1000"),"Completed"),0)) | D23: =IF(Config!A11="","",IFERROR(COUNTIF(INDIRECT("'"&Config!A11&"'!B2:B1000"),"In Progress"),0)) | E23: =IF(Config!A11="","",IFERROR(COUNTIF(INDIRECT("'"&Config!A11&"'!B2:B1000"),"Overdue"),0)) | F23: =IF(Config!A11="","",IFERROR(COUNTIF(INDIRECT("'"&Config!A11&"'!B2:B1000"),"Not Started"),0)) | G23: =IF(Config!A11="","",IFERROR(COUNTIF(INDIRECT("'"&Config!A11&"'!B2:B1000"),"Completed")/COUNTA(INDIRECT("'"&Config!A11&"'!B2:B1000")),0)) | R23: =IF(Config!A16="","",Config!A16) | S23: =IF(Config!A16="","",F205)
A24: =IF(Config!A12="","",Config!A12) | B24: =IF(Config!A12="","",IFERROR(COUNTA(INDIRECT("'"&Config!A12&"'!B2:B1000")),0)) | C24: =IF(Config!A12="","",IFERROR(COUNTIF(INDIRECT("'"&Config!A12&"'!B2:B1000"),"Completed"),0)) | D24: =IF(Config!A12="","",IFERROR(COUNTIF(INDIRECT("'"&Config!A12&"'!B2:B1000"),"In Progress"),0)) | E24: =IF(Config!A12="","",IFERROR(COUNTIF(INDIRECT("'"&Config!A12&"'!B2:B1000"),"Overdue"),0)) | F24: =IF(Config!A12="","",IFERROR(COUNTIF(INDIRECT("'"&Config!A12&"'!B2:B1000"),"Not Started"),0)) | G24: =IF(Config!A12="","",IFERROR(COUNTIF(INDIRECT("'"&Config!A12&"'!B2:B1000"),"Completed")/COUNTA(INDIRECT("'"&Config!A12&"'!B2:B1000")),0)) | R24: =IF(Config!A17="","",Config!A17) | S24: =IF(Config!A17="","",F206)
A25: =IF(Config!A13="","",Config!A13) | B25: =IF(Config!A13="","",IFERROR(COUNTA(INDIRECT("'"&Config!A13&"'!B2:B1000")),0)) | C25: =IF(Config!A13="","",IFERROR(COUNTIF(INDIRECT("'"&Config!A13&"'!B2:B1000"),"Completed"),0)) | D25: =IF(Config!A13="","",IFERROR(COUNTIF(INDIRECT("'"&Config!A13&"'!B2:B1000"),"In Progress"),0)) | E25: =IF(Config!A13="","",IFERROR(COUNTIF(INDIRECT("'"&Config!A13&"'!B2:B1000"),"Overdue"),0)) | F25: =IF(Config!A13="","",IFERROR(COUNTIF(INDIRECT("'"&Config!A13&"'!B2:B1000"),"Not Started"),0)) | G25: =IF(Config!A13="","",IFERROR(COUNTIF(INDIRECT("'"&Config!A13&"'!B2:B1000"),"Completed")/COUNTA(INDIRECT("'"&Config!A13&"'!B2:B1000")),0)) | R25: =IF(Config!A18="","",Config!A18) | S25: =IF(Config!A18="","",F207)
A26: =IF(Config!A14="","",Config!A14) | B26: =IF(Config!A14="","",IFERROR(COUNTA(INDIRECT("'"&Config!A14&"'!B2:B1000")),0)) | C26: =IF(Config!A14="","",IFERROR(COUNTIF(INDIRECT("'"&Config!A14&"'!B2:B1000"),"Completed"),0)) | D26: =IF(Config!A14="","",IFERROR(COUNTIF(INDIRECT("'"&Config!A14&"'!B2:B1000"),"In Progress"),0)) | E26: =IF(Config!A14="","",IFERROR(COUNTIF(INDIRECT("'"&Config!A14&"'!B2:B1000"),"Overdue"),0)) | F26: =IF(Config!A14="","",IFERROR(COUNTIF(INDIRECT("'"&Config!A14&"'!B2:B1000"),"Not Started"),0)) | G26: =IF(Config!A14="","",IFERROR(COUNTIF(INDIRECT("'"&Config!A14&"'!B2:B1000"),"Completed")/COUNTA(INDIRECT("'"&Config!A14&"'!B2:B1000")),0)) | R26: =IF(Config!A19="","",Config!A19) | S26: =IF(Config!A19="","",F208)
A27: =IF(Config!A15="","",Config!A15) | B27: =IF(Config!A15="","",IFERROR(COUNTA(INDIRECT("'"&Config!A15&"'!B2:B1000")),0)) | C27: =IF(Config!A15="","",IFERROR(COUNTIF(INDIRECT("'"&Config!A15&"'!B2:B1000"),"Completed"),0)) | D27: =IF(Config!A15="","",IFERROR(COUNTIF(INDIRECT("'"&Config!A15&"'!B2:B1000"),"In Progress"),0)) | E27: =IF(Config!A15="","",IFERROR(COUNTIF(INDIRECT("'"&Config!A15&"'!B2:B1000"),"Overdue"),0)) | F27: =IF(Config!A15="","",IFERROR(COUNTIF(INDIRECT("'"&Config!A15&"'!B2:B1000"),"Not Started"),0)) | G27: =IF(Config!A15="","",IFERROR(COUNTIF(INDIRECT("'"&Config!A15&"'!B2:B1000"),"Completed")/COUNTA(INDIRECT("'"&Config!A15&"'!B2:B1000")),0)) | R27: =IF(Config!A20="","",Config!A20) | S27: =IF(Config!A20="","",F209)
... A30: =IF(Config!A18="","",Config!A18) | B30: =IF(Config!A18="","",IFERROR(COUNTA(INDIRECT("'"&Config!A18&"'!B2:B1000")),0)) | C30: =IF(Config!A18="","",IFERROR(COUNTIF(INDIRECT("'"&Config!A18&"'!B2:B1000"),"Completed"),0)) | D30: =IF(Config!A18="","",IFERROR(COUNTIF(INDIRECT("'"&Config!A18&"'!B2:B1000"),"In Progress"),0)) | E30: =IF(Config!A18="","",IFERROR(COUNTIF(INDIRECT("'"&Config!A18&"'!B2:B1000"),"Overdue"),0)) | F30: =IF(Config!A18="","",IFERROR(COUNTIF(INDIRECT("'"&Config!A18&"'!B2:B1000"),"Not Started"),0)) | G30: =IF(Config!A18="","",IFERROR(COUNTIF(INDIRECT("'"&Config!A18&"'!B2:B1000"),"Completed")/COUNTA(INDIRECT("'"&Config!A18&"'!B2:B1000")),0)) | R30: =IF(Config!A23="","",Config!A23) | S30: =IF(Config!A23="","",F212)
A31: =IF(Config!A19="","",Config!A19) | B31: =IF(Config!A19="","",IFERROR(COUNTA(INDIRECT("'"&Config!A19&"'!B2:B1000")),0)) | C31: =IF(Config!A19="","",IFERROR(COUNTIF(INDIRECT("'"&Config!A19&"'!B2:B1000"),"Completed"),0)) | D31: =IF(Config!A19="","",IFERROR(COUNTIF(INDIRECT("'"&Config!A19&"'!B2:B1000"),"In Progress"),0)) | E31: =IF(Config!A19="","",IFERROR(COUNTIF(INDIRECT("'"&Config!A19&"'!B2:B1000"),"Overdue"),0)) | F31: =IF(Config!A19="","",IFERROR(COUNTIF(INDIRECT("'"&Config!A19&"'!B2:B1000"),"Not Started"),0)) | G31: =IF(Config!A19="","",IFERROR(COUNTIF(INDIRECT("'"&Config!A19&"'!B2:B1000"),"Completed")/COUNTA(INDIRECT("'"&Config!A19&"'!B2:B1000")),0))
A32: =IF(Config!A20="","",Config!A20) | B32: =IF(Config!A20="","",IFERROR(COUNTA(INDIRECT("'"&Config!A20&"'!B2:B1000")),0)) | C32: =IF(Config!A20="","",IFERROR(COUNTIF(INDIRECT("'"&Config!A20&"'!B2:B1000"),"Completed"),0)) | D32: =IF(Config!A20="","",IFERROR(COUNTIF(INDIRECT("'"&Config!A20&"'!B2:B1000"),"In Progress"),0)) | E32: =IF(Config!A20="","",IFERROR(COUNTIF(INDIRECT("'"&Config!A20&"'!B2:B1000"),"Overdue"),0)) | F32: =IF(Config!A20="","",IFERROR(COUNTIF(INDIRECT("'"&Config!A20&"'!B2:B1000"),"Not Started"),0)) | G32: =IF(Config!A20="","",IFERROR(COUNTIF(INDIRECT("'"&Config!A20&"'!B2:B1000"),"Completed")/COUNTA(INDIRECT("'"&Config!A20&"'!B2:B1000")),0))
A33: =IF(Config!A21="","",Config!A21) | B33: =IF(Config!A21="","",IFERROR(COUNTA(INDIRECT("'"&Config!A21&"'!B2:B1000")),0)) | C33: =IF(Config!A21="","",IFERROR(COUNTIF(INDIRECT("'"&Config!A21&"'!B2:B1000"),"Completed"),0)) | D33: =IF(Config!A21="","",IFERROR(COUNTIF(INDIRECT("'"&Config!A21&"'!B2:B1000"),"In Progress"),0)) | E33: =IF(Config!A21="","",IFERROR(COUNTIF(INDIRECT("'"&Config!A21&"'!B2:B1000"),"Overdue"),0)) | F33: =IF(Config!A21="","",IFERROR(COUNTIF(INDIRECT("'"&Config!A21&"'!B2:B1000"),"Not Started"),0)) | G33: =IF(Config!A21="","",IFERROR(COUNTIF(INDIRECT("'"&Config!A21&"'!B2:B1000"),"Completed")/COUNTA(INDIRECT("'"&Config!A21&"'!B2:B1000")),0))
A34: =IF(Config!A22="","",Config!A22) | B34: =IF(Config!A22="","",IFERROR(COUNTA(INDIRECT("'"&Config!A22&"'!B2:B1000")),0)) | C34: =IF(Config!A22="","",IFERROR(COUNTIF(INDIRECT("'"&Config!A22&"'!B2:B1000"),"Completed"),0)) | D34: =IF(Config!A22="","",IFERROR(COUNTIF(INDIRECT("'"&Config!A22&"'!B2:B1000"),"In Progress"),0)) | E34: =IF(Config!A22="","",IFERROR(COUNTIF(INDIRECT("'"&Config!A22&"'!B2:B1000"),"Overdue"),0)) | F34: =IF(Config!A22="","",IFERROR(COUNTIF(INDIRECT("'"&Config!A22&"'!B2:B1000"),"Not Started"),0)) | G34: =IF(Config!A22="","",IFERROR(COUNTIF(INDIRECT("'"&Config!A22&"'!B2:B1000"),"Completed")/COUNTA(INDIRECT("'"&Config!A22&"'!B2:B1000")),0))
A35: =IF(Config!A23="","",Config!A23) | B35: =IF(Config!A23="","",IFERROR(COUNTA(INDIRECT("'"&Config!A23&"'!B2:B1000")),0)) | C35: =IF(Config!A23="","",IFERROR(COUNTIF(INDIRECT("'"&Config!A23&"'!B2:B1000"),"Completed"),0)) | D35: =IF(Config!A23="","",IFERROR(COUNTIF(INDIRECT("'"&Config!A23&"'!B2:B1000"),"In Progress"),0)) | E35: =IF(Config!A23="","",IFERROR(COUNTIF(INDIRECT("'"&Config!A23&"'!B2:B1000"),"Overdue"),0)) | F35: =IF(Config!A23="","",IFERROR(COUNTIF(INDIRECT("'"&Config!A23&"'!B2:B1000"),"Not Started"),0)) | G35: =IF(Config!A23="","",IFERROR(COUNTIF(INDIRECT("'"&Config!A23&"'!B2:B1000"),"Completed")/COUNTA(INDIRECT("'"&Config!A23&"'!B2:B1000")),0))
A36: TOTALS | B36: =SUM(B16:B35) -> 76 | C36: =SUM(C16:C35) -> 0 | D36: =SUM(D16:D35) -> 0 | E36: =SUM(E16:E35) -> 1 | F36: =SUM(F16:F35) -> 75 | G36: =IFERROR(C36/B36,0) -> 0
A38: 🏷️ PRIORITY CLASS DISTRIBUTION
A39: Project | B39: Must | C39: Should | D39: Could | E39: Wont | F39: Want
A40: =IF(Config!A4="","",Config!A4) -> ODC Cleanup | B40: =IF(Config!A4="","",IFERROR(COUNTIF(INDIRECT("'"&Config!A4&"'!L2:L1000"),"Must"),0)) -> 0 | C40: =IF(Config!A4="","",IFERROR(COUNTIF(INDIRECT("'"&Config!A4&"'!L2:L1000"),"Should"),0)) -> 1 | D40: =IF(Config!A4="","",IFERROR(COUNTIF(INDIRECT("'"&Config!A4&"'!L2:L1000"),"Could"),0)) -> 0 | E40: =IF(Config!A4="","",IFERROR(COUNTIF(INDIRECT("'"&Config!A4&"'!L2:L1000"),"Wont"),0)) -> 1 | F40: =IF(Config!A4="","",IFERROR(COUNTIF(INDIRECT("'"&Config!A4&"'!L2:L1000"),"Want"),0)) -> 0
A41: =IF(Config!A5="","",Config!A5) -> Datastore Reclamation | B41: =IF(Config!A5="","",IFERROR(COUNTIF(INDIRECT("'"&Config!A5&"'!L2:L1000"),"Must"),0)) -> 0 | C41: =IF(Config!A5="","",IFERROR(COUNTIF(INDIRECT("'"&Config!A5&"'!L2:L1000"),"Should"),0)) -> 2 | D41: =IF(Config!A5="","",IFERROR(COUNTIF(INDIRECT("'"&Config!A5&"'!L2:L1000"),"Could"),0)) -> 0 | E41: =IF(Config!A5="","",IFERROR(COUNTIF(INDIRECT("'"&Config!A5&"'!L2:L1000"),"Wont"),0)) -> 1 | F41: =IF(Config!A5="","",IFERROR(COUNTIF(INDIRECT("'"&Config!A5&"'!L2:L1000"),"Want"),0)) -> 1
A42: =IF(Config!A6="","",Config!A6) -> Retired VM Cleanup | B42: =IF(Config!A6="","",IFERROR(COUNTIF(INDIRECT("'"&Config!A6&"'!L2:L1000"),"Must"),0)) -> 0 | C42: =IF(Config!A6="","",IFERROR(COUNTIF(INDIRECT("'"&Config!A6&"'!L2:L1000"),"Should"),0)) -> 0 | D42: =IF(Config!A6="","",IFERROR(COUNTIF(INDIRECT("'"&Config!A6&"'!L2:L1000"),"Could"),0)) -> 0 | E42: =IF(Config!A6="","",IFERROR(COUNTIF(INDIRECT("'"&Config!A6&"'!L2:L1000"),"Wont"),0)) -> 0 | F42: =IF(Config!A6="","",IFERROR(COUNTIF(INDIRECT("'"&Config!A6&"'!L2:L1000"),"Want"),0)) -> 0
A43: =IF(Config!A7="","",Config!A7) -> Zerto Scripts | B43: =IF(Config!A7="","",IFERROR(COUNTIF(INDIRECT("'"&Config!A7&"'!L2:L1000"),"Must"),0)) -> 0 | C43: =IF(Config!A7="","",IFERROR(COUNTIF(INDIRECT("'"&Config!A7&"'!L2:L1000"),"Should"),0)) -> 0 | D43: =IF(Config!A7="","",IFERROR(COUNTIF(INDIRECT("'"&Config!A7&"'!L2:L1000"),"Could"),0)) -> 0 | E43: =IF(Config!A7="","",IFERROR(COUNTIF(INDIRECT("'"&Config!A7&"'!L2:L1000"),"Wont"),0)) -> 0 | F43: =IF(Config!A7="","",IFERROR(COUNTIF(INDIRECT("'"&Config!A7&"'!L2:L1000"),"Want"),0)) -> 0
A44: =IF(Config!A8="","",Config!A8) | B44: =IF(Config!A8="","",IFERROR(COUNTIF(INDIRECT("'"&Config!A8&"'!L2:L1000"),"Must"),0)) | C44: =IF(Config!A8="","",IFERROR(COUNTIF(INDIRECT("'"&Config!A8&"'!L2:L1000"),"Should"),0)) | D44: =IF(Config!A8="","",IFERROR(COUNTIF(INDIRECT("'"&Config!A8&"'!L2:L1000"),"Could"),0)) | E44: =IF(Config!A8="","",IFERROR(COUNTIF(INDIRECT("'"&Config!A8&"'!L2:L1000"),"Wont"),0)) | F44: =IF(Config!A8="","",IFERROR(COUNTIF(INDIRECT("'"&Config!A8&"'!L2:L1000"),"Want"),0))
...

Sheet ODC Cleanup
A1: Action Item | B1: Status | C1: Phase | D1: Category | E1: Priority | F1: Owner | G1: Responsibility | H1: Assigned Date | I1: Due Date | J1: Challenges | K1: Progress % | L1: Priority Class
A2: Project Start | B2: Not Started | C2: Planning | D2: admin | E2: Medium | F2: Owner | G2: required | H2: 46130.998 | I2: 46144.998 | K2: 0 | L2: Should
A3: - Create Project Sheet | B3: Not Started | C3: Planning | D3: admin | E3: Medium | F3: Owner | G3: required | H3: 46130.998 | I3: 46144.998 | K3: 0
A4: - Create Confluence Project Page | B4: Not Started | C4: Planning | D4: admin | E4: Medium | F4: Owner | G4: required | H4: 46130.998 | I4: 46144.998 | K4: 0 | L4: Wont
A5: - Review Acceptance Criteria | B5: Not Started | C5: Planning | D5: admin | E5: Medium | F5: Owner | G5: required | H5: 46130.998 | I5: 46144.998 | K5: 0
A6: Requirements Gathering | B6: Not Started | C6: Requirements | D6: admin | E6: Medium | F6: Owner | G6: required | H6: 46130.998 | I6: 46144.998 | K6: 0
A7: - Meeting with Stakeholders | B7: Not Started | C7: Requirements | D7: admin | E7: Medium | F7: Owner | G7: required | H7: 46130.998 | I7: 46144.998 | K7: 0
A8: - Refine Acceptance Criteria | B8: Not Started | C8: Requirements | D8: admin | E8: Medium | F8: Owner | G8: required | H8: 46130.998 | I8: 46144.998 | J8: Abbey is hurting me | K8: 0
A9: - Define MVP | B9: Not Started | C9: Requirements | D9: admin | E9: Medium | F9: Owner | G9: required | H9: 46130.998 | I9: 46144.998 | K9: 0
A10: - Define FR, NFR, AC, US | B10: Not Started | C10: Requirements | D10: admin | E10: Medium | F10: Owner | G10: required | H10: 46130.998 | I10: 46144.998 | K10: 0
A11: Design | B11: Not Started | C11: Design | D11: admin | E11: Medium | F11: Owner | G11: required | H11: 46130.998 | I11: 46144.998 | K11: 0
A12: - Draw C4 Docs | B12: Not Started | C12: Design | D12: admin | E12: Medium | F12: Owner | G12: should have | H12: 46130.998 | I12: 46144.998 | K12: 0
A13: Implementation | B13: Not Started | C13: Implementation | D13: admin | E13: Medium | F13: Owner | G13: required | H13: 46130.998 | I13: 46144.998 | K13: 0
A14: - Create Doctor Patient | B14: Not Started | C14: Implementation | D14: admin | E14: Medium | F14: Owner | G14: required | H14: 46130.998 | I14: 46144.998 | K14: 0
A15: - PR to Main | B15: Overdue | C15: Implementation | D15: admin | E15: Medium | F15: Owner | G15: nice to have | H15: 46130.998 | I15: 46144.998 | K15: 0
A16: - ReadMe | B16: Not Started | C16: Implementation | D16: admin | E16: Medium | F16: Owner | G16: should have | H16: 46130.998 | I16: 46144.998 | K16: 0
A17: Monitoring | B17: Not Started | C17: Monitoring | D17: admin | E17: Medium | F17: Owner | G17: required | H17: 46130.998 | I17: 46144.998 | K17: 0
A18: - Splunk Forwarder Configured | B18: Not Started | C18: Monitoring | D18: admin | E18: Medium | F18: Owner | G18: nice to have | H18: 46130.998 | I18: 46144.998 | K18: 0
A19: - Splunk Dashboard | B19: Not Started | C19: Monitoring | D19: admin | E19: Low | F19: Owner | G19: nice to have | H19: 46130.998 | I19: 46144.998 | K19: 0
A20: - Dynatrace Telemetry | B20: Not Started | C20: Monitoring | D20: admin | E20: Medium | F20: Owner | G20: nice to have | H20: 46130.998 | I20: 46144.998 | K20: 0

Sheet Datastore Reclamation
A1: Action Item | B1: Status | C1: Phase | D1: Category | E1: Priority | F1: Owner | G1: Responsibility | H1: Assigned Date | I1: Due Date | J1: Challenges | K1: Progress % | L1: Priority Class
A2: Project Start | B2: Not Started | C2: Planning | D2: admin | E2: Medium | F2: Owner | G2: required | H2: 46130.998 | I2: 46144.998 | J2: None | K2: 0
A3: - Create Project Sheet | B3: Not Started | C3: Planning | D3: admin | E3: Medium | F3: Owner | G3: required | H3: 46130.998 | I3: 46144.998 | J3: None | K3: 0
A4: - Create Confluence Project Page | B4: Not Started | C4: Planning | D4: admin | E4: Medium | F4: Owner | G4: required | H4: 46130.998 | I4: 46144.998 | J4: None | K4: 0
A5: - Review Acceptance Criteria | B5: Not Started | C5: Planning | D5: admin | E5: Medium | F5: Owner | G5: required | H5: 46130.998 | I5: 46144.998 | J5: None | K5: 0
A6: Requirements Gathering | B6: Not Started | C6: Requirements | D6: admin | E6: Medium | F6: Owner | G6: required | H6: 46130.998 | I6: 46144.998 | J6: None | K6: 0
A7: - Meeting with Stakeholders | B7: Not Started | C7: Requirements | D7: admin | E7: Medium | F7: Owner | G7: required | H7: 46130.998 | I7: 46144.998 | J7: None | K7: 0
A8: - Refine Acceptance Criteria | B8: Not Started | C8: Requirements | D8: admin | E8: Medium | F8: Owner | G8: required | H8: 46130.998 | I8: 46144.998 | J8: None | K8: 0
A9: - Define MVP | B9: Not Started | C9: Requirements | D9: admin | E9: Medium | F9: Owner | G9: required | H9: 46130.998 | I9: 46144.998 | J9: None | K9: 0
A10: - Define FR, NFR, AC, US | B10: Not Started | C10: Requirements | D10: admin | E10: Medium | F10: Owner | G10: required | H10: 46130.998 | I10: 46144.998 | J10: None | K10: 0 | L10: Wont
A11: Design | B11: Not Started | C11: Design | D11: admin | E11: Medium | F11: Owner | G11: required | H11: 46130.998 | I11: 46144.998 | J11: None | K11: 0
A12: - Draw C4 Docs | B12: Not Started | C12: Design | D12: admin | E12: Medium | F12: Owner | G12: required | H12: 46130.998 | I12: 46144.998 | J12: None | K12: 0
A13: Implementation | B13: Not Started | C13: Implementation | D13: admin | E13: Medium | F13: Owner | G13: required | H13: 46130.998 | I13: 46144.998 | J13: None | K13: 0
A14: - Create Doctor Patient | B14: Not Started | C14: Implementation | D14: admin | E14: Medium | F14: Owner | G14: required | H14: 46130.998 | I14: 46144.998 | J14: None | K14: 0
A15: - PR to Main | B15: Not Started | C15: Implementation | D15: admin | E15: Medium | F15: Owner | G15: required | H15: 46130.998 | I15: 46144.998 | J15: None | K15: 0
A16: - ReadMe | B16: Not Started | C16: Implementation | D16: admin | E16: Medium | F16: Owner | G16: required | H16: 46130.998 | I16: 46144.998 | J16: None | K16: 0 | L16: Should
A17: Monitoring | B17: Not Started | C17: Monitoring | D17: admin | E17: Medium | F17: Owner | G17: required | H17: 46130.998 | I17: 46144.998 | J17: None | K17: 0
A18: - Splunk Forwarder Configured | B18: Not Started | C18: Monitoring | D18: admin | E18: Medium | F18: Owner | G18: required | H18: 46130.998 | I18: 46144.998 | J18: None | K18: 0 | L18: Should
A19: - Splunk Dashboard | B19: Not Started | C19: Monitoring | D19: admin | E19: Medium | F19: Owner | G19: required | H19: 46130.998 | I19: 46144.998 | J19: None | K19: 0
A20: - Dynatrace Telemetry | B20: Not Started | C20: Monitoring | D20: admin | E20: Medium | F20: Owner | G20: required | H20: 46130.998 | I20: 46144.998 | J20: None | K20: 0 | L20: Want

Sheet Retired VM Cleanup
A1: Action Item | B1: Status | C1: Phase | D1: Category | E1: Priority | F1: Owner | G1: Responsibility | H1: Assigned Date | I1: Due Date | J1: Challenges | K1: Progress % | L1: Priority Class
A2: Project Start | B2: Not Started | C2: Planning | D2: admin | E2: Medium | F2: Owner | G2: required | H2: 46130.998 | I2: 46144.998 | J2: None | K2: 0
A3: - Create Project Sheet | B3: Not Started | C3: Planning | D3: admin | E3: Medium | F3: Owner | G3: required | H3: 46130.998 | I3: 46144.998 | J3: None | K3: 0
A4: - Create Confluence Project Page | B4: Not Started | C4: Planning | D4: admin | E4: Medium | F4: Owner | G4: required | H4: 46130.998 | I4: 46144.998 | J4: None | K4: 0
A5: - Review Acceptance Criteria | B5: Not Started | C5: Planning | D5: admin | E5: Medium | F5: Owner | G5: required | H5: 46130.998 | I5: 46144.998 | J5: None | K5: 0
A6: Requirements Gathering | B6: Not Started | C6: Requirements | D6: admin | E6: Medium | F6: Owner | G6: required | H6: 46130.998 | I6: 46144.998 | J6: None | K6: 0
A7: - Meeting with Stakeholders | B7: Not Started | C7: Requirements | D7: admin | E7: Medium | F7: Owner | G7: required | H7: 46130.998 | I7: 46144.998 | J7: None | K7: 0
A8: - Refine Acceptance Criteria | B8: Not Started | C8: Requirements | D8: admin | E8: Medium | F8: Owner | G8: required | H8: 46130.998 | I8: 46144.998 | J8: None | K8: 0
A9: - Define MVP | B9: Not Started | C9: Requirements | D9: admin | E9: Medium | F9: Owner | G9: required | H9: 46130.998 | I9: 46144.998 | J9: None | K9: 0
A10: - Define FR, NFR, AC, US | B10: Not Started | C10: Requirements | D10: admin | E10: Medium | F10: Owner | G10: required | H10: 46130.998 | I10: 46144.998 | J10: None | K10: 0
A11: Design | B11: Not Started | C11: Design | D11: admin | E11: Medium | F11: Owner | G11: required | H11: 46130.998 | I11: 46144.998 | J11: None | K11: 0
A12: - Draw C4 Docs | B12: Not Started | C12: Design | D12: admin | E12: Medium | F12: Owner | G12: required | H12: 46130.998 | I12: 46144.998 | J12: None | K12: 0
A13: Implementation | B13: Not Started | C13: Implementation | D13: admin | E13: Medium | F13: Owner | G13: required | H13: 46130.998 | I13: 46144.998 | J13: None | K13: 0
... A20: - Dynatrace Telemetry | B20: Not Started | C20: Monitoring | D20: admin | E20: Medium | F20: Owner | G20: required | H20: 46130.998 | I20: 46144.998 | J20: None | K20: 0

Sheet Zerto Scripts
A1: Action Item | B1: Status | C1: Phase | D1: Category | E1: Priority | F1: Owner | G1: Responsibility | H1: Assigned Date | I1: Due Date | J1: Challenges | K1: Progress % | L1: Priority Class
A2: Project Start | B2: Not Started | C2: Planning | D2: admin | E2: Medium | F2: Owner | G2: required | H2: 46130.998 | I2: 46144.998 | J2: None | K2: 0
A3: - Create Project Sheet | B3: Not Started | C3: Planning | D3: admin | E3: Medium | F3: Owner | G3: required | H3: 46130.998 | I3: 46144.998 | J3: None | K3: 0
A4: - Create Confluence Project Page | B4: Not Started | C4: Planning | D4: admin | E4: Medium | F4: Owner | G4: required | H4: 46130.998 | I4: 46144.998 | J4: None | K4: 0
A5: - Review Acceptance Criteria | B5: Not Started | C5: Planning | D5: admin | E5: Medium | F5: Owner | G5: required | H5: 46130.998 | I5: 46144.998 | J5: None | K5: 0
A6: Requirements Gathering | B6: Not Started | C6: Requirements | D6: admin | E6: Medium | F6: Owner | G6: required | H6: 46130.998 | I6: 46144.998 | J6: None | K6: 0
A7: - Meeting with Stakeholders | B7: Not Started | C7: Requirements | D7: admin | E7: Medium | F7: Owner | G7: required | H7: 46130.998 | I7: 46144.998 | J7: None | K7: 0
A8: - Refine Acceptance Criteria | B8: Not Started | C8: Requirements | D8: admin | E8: Medium | F8: Owner | G8: required | H8: 46130.998 | I8: 46144.998 | J8: None | K8: 0
A9: - Define MVP | B9: Not Started | C9: Requirements | D9: admin | E9: Medium | F9: Owner | G9: required | H9: 46130.998 | I9: 46144.998 | J9: None | K9: 0
A10: - Define FR, NFR, AC, US | B10: Not Started | C10: Requirements | D10: admin | E10: Medium | F10: Owner | G10: required | H10: 46130.998 | I10: 46144.998 | J10: None | K10: 0
A11: Design | B11: Not Started | C11: Design | D11: admin | E11: Medium | F11: Owner | G11: required | H11: 46130.998 | I11: 46144.998 | J11: None | K11: 0
A12: - Draw C4 Docs | B12: Not Started | C12: Design | D12: admin | E12: Medium | F12: Owner | G12: required | H12: 46130.998 | I12: 46144.998 | J12: None | K12: 0
A13: Implementation | B13: Not Started | C13: Implementation | D13: admin | E13: Medium | F13: Owner | G13: required | H13: 46130.998 | I13: 46144.998 | J13: None | K13: 0
... A20: - Dynatrace Telemetry | B20: Not Started | C20: Monitoring | D20: admin | E20: Medium | F20: Owner | G20: required | H20: 46130.998 | I20: 46144.998 | J20: None | K20: 0
